Workbook

Sheet GASTOS PLANIFICADOS
A1: GASTOS PLANIFICADOS | B1: ENE | C1: FEB | D1: MAR | E1: ABR | F1: MAY | G1: JUN | H1: JUL | I1: AGO | J1: SEP | K1: OCT | L1: NOV | M1: DIC | N1: AÑO
A2: Centro de Costos de Producción / Operaciones | B2: Ene | C2: Feb | D2: Mar | E2: Abr | F2: Mayo | G2: Jun | H2: Jul | I2: Ago | J2: Sep | K2: Oct | L2: Nov | M2: Dic | N2: AÑO
A3: Salarios | F3: 10000 | N3: =SUM(B3:M3) -> 10000
A9: Beneficios | N9: =SUM(B9:M9) -> 0
A10: Subtotal | B10: =SUM(B3:B9) -> 0 | C10: =SUM(C3:C9) -> 0 | D10: =SUM(D3:D9) -> 0 | E10: =SUM(E3:E9) -> 0 | F10: =SUM(F3:F9) -> 10000 | G10: =SUM(G3:G9) -> 0 | H10: =SUM(H3:H9) -> 0 | I10: =SUM(I3:I9) -> 0 | ... N10: =SUM(N3:N9) -> 10000
A12: Centro de Costos de Ventas | B12: Ene | C12: Feb | D12: Mar | E12: Abr | F12: Mayo | G12: Jun | H12: Jul | I12: Ago | J12: Sep | K12: Oct | L12: Nov | M12: Dic | N12: AÑO
A13: Sueldo Vendedores | F13: 9800 | G13: 9800 | H13: 9800 | I13: 9800 | J13: 9800 | K13: 9800 | L13: 9800 | M13: 9800 | N13: =SUM(B13:M13) -> 78400
A14: Comisiones | F14: 100 | G14: 100 | H14: 100 | I14: 100 | J14: 100 | K14: 100 | L14: 400 | M14: 400 | N14: =SUM(B14:M14) -> 1400
A15: Viaticos | F15: 300 | G15: 300 | H15: 300 | I15: 300 | J15: 300 | K15: 300 | L15: 300 | M15: 300 | N15: =SUM(B15:M15) -> 2400
A16: Capacitaciones | F16: 40 | G16: 40 | H16: 40 | I16: 40 | J16: 40 | K16: 40 | L16: 40 | M16: 40 | N16: =SUM(B16:M16) -> 320
A17: Movilidad Comercial
A18: Facebook Ads | F18: 250 | G18: 250 | H18: 250 | I18: 250 | J18: 250 | K18: 250 | L18: 250 | M18: 250 | N18: =SUM(B18:M18) -> 2000
A19: Telefonia Ventas
A20: Google Ads | F20: 180 | G20: 180 | H20: 180 | I20: 180 | J20: 180 | K20: 180 | L20: 180 | M20: 180 | N20: =SUM(B20:M20) -> 1440
A21: Subtotal | B21: =SUM(B4:B20) -> 0 | C21: =SUM(C4:C20) -> 0 | D21: =SUM(D4:D20) -> 0 | E21: =SUM(E13:E20) -> 0 | F21: =SUM(F13:F20) -> 10670 | G21: =SUM(G13:G20) -> 10670 | H21: =SUM(H13:H20) -> 10670 | I21: =SUM(I13:I20) -> 10670 | J21: =SUM(J13:J20) -> 10670 | K21: =SUM(K13:K20) -> 10670 | L21: =SUM(L13:L20) -> 10970 | M21: =SUM(M13:M20) -> 10970 | N21: =SUM(B21:M21) -> 85960
A22: Centro de Costos de Marketing | B22: Ene | C22: Feb | D22: Mar | E22: Abr | F22: Mayo | G22: Jun | H22: Jul | I22: Ago | J22: Sep | K22: Oct | L22: Nov | M22: Dic | N22: AÑO
A23: Sueldo Vendedores | N23: =SUM(B23:M23) -> 0
A24: Produccion audiovisual | F24: 200 | G24: 200 | H24: 200 | I24: 200 | J24: 200 | K24: 200 | L24: 200 | M24: 200 | N24: =SUM(B24:M24) -> 1600
A25: Merchandising | N25: =SUM(B25:M25) -> 0
A26: Eventos | N26: =SUM(B26:M26) -> 0
A27: Regalos Corporativos | N27: =SUM(B27:M27) -> 0
A28: Facebook Ads | F28: 600 | G28: 600 | H28: 600 | I28: 600 | J28: 600 | K28: 600 | L28: 600 | M28: 600 | N28: =SUM(B28:M28) -> 4800
A29: Telefonia Comercial | N29: =SUM(B29:M29) -> 0
A30: Subtotal | B30: =SUM(B13:B29) -> 0 | C30: =SUM(C13:C29) -> 0 | D30: =SUM(D13:D29) -> 0 | E30: =SUM(E23:E29) -> 0 | F30: =SUM(F23:F29) -> 800 | G30: =SUM(G23:G29) -> 800 | H30: =SUM(H23:H29) -> 800 | I30: =SUM(I23:I29) -> 800 | J30: =SUM(J23:J29) -> 800 | K30: =SUM(K23:K29) -> 800 | L30: =SUM(L23:L29) -> 800 | M30: =SUM(M23:M29) -> 800 | N30: =SUM(B30:M30) -> 6400
A31: Subtotal | B31: =SUM(B14:B30) -> 0 | C31: =SUM(C14:C30) -> 0 | D31: =SUM(D14:D30) -> 0 | E31: =+E21+E30 -> 0 | F31: =+F21+F30 -> 11470 | G31: =+G21+G30 -> 11470 | H31: =+H21+H30 -> 11470 | I31: =+I21+I30 -> 11470 | J31: =+J21+J30 -> 11470 | K31: =+K21+K30 -> 11470 | L31: =+L21+L30 -> 11770 | ... N31: =+N21+N30 -> 92360
A33: Centro de Costos Administrativos (Generales) | B33: Ene | C33: Feb | D33: Mar | E33: Abr | F33: Mayo | G33: Jun | H33: Jul | I33: Ago | J33: Sep | K33: Oct | L33: Nov | M33: Dic | N33: AÑO
A34: Sueldo Administrativo | F34: 500 | G34: 500 | H34: 500 | I34: 500 | J34: 500 | K34: 500 | L34: 500 | M34: 500 | N34: =SUM(B34:M34) -> 4000
A35: Sueldo Gerencia
A36: Sueldo Contabilidad
A37: RRHH
A38: Internet
A39: Telefonia
A40: Agua
A41: Luz
A42: Alquiler Local
A43: Vigilancia
A44: Utiles de Oficina
A45: Paleria
A46: Impresiones
A47: Licencias software | F47: 200 | G47: 1000 | H47: 200 | I47: 200 | J47: 200 | K47: 200 | L47: 200 | M47: 1000 | N47: =SUM(B47:M47) -> 3200
...

Sheet GASTOS REALES
A1: GASTOS PLANIFICADOS | B1: ENE | C1: FEB | D1: MAR | E1: ABR | F1: MAY | G1: JUN | H1: JUL | I1: AGO | J1: SEP | K1: OCT | L1: NOV | M1: DIC | N1: AÑO
A2: Centro de Costos de Producción / Operaciones | B2: Ene | C2: Feb | D2: Mar | E2: Abr | F2: Mayo | G2: Jun | H2: Jul | I2: Ago | J2: Sep | K2: Oct | L2: Nov | M2: Dic | N2: AÑO
A3: Salarios | F3: 2000 | G3: 4000 | N3: =SUM(B3:M3) -> 6000
A9: Beneficios | N9: =SUM(B9:M9) -> 0
A10: Subtotal | B10: =SUM(B3:B9) -> 0 | C10: =SUM(C3:C9) -> 0 | D10: =SUM(D3:D9) -> 0 | E10: =SUM(E3:E9) -> 0 | F10: =SUM(F3:F9) -> 2000 | G10: =SUM(G3:G9) -> 4000 | H10: =SUM(H3:H9) -> 0 | I10: =SUM(I3:I9) -> 0 | ... N10: =SUM(N3:N9) -> 6000
A12: Centro de Costos de Ventas | B12: Ene | C12: Feb | D12: Mar | E12: Abr | F12: Mayo | G12: Jun | H12: Jul | I12: Ago | J12: Sep | K12: Oct | L12: Nov | M12: Dic | N12: AÑO
A13: Sueldo Vendedores | F13: 9800 | G13: 9800 | H13: 9800 | I13: 9800 | J13: 9800 | K13: 9800 | L13: 9800 | M13: 9800 | N13: =SUM(B13:M13) -> 78400
A14: Comisiones | F14: 100 | G14: 100 | H14: 100 | I14: 100 | J14: 100 | K14: 100 | L14: 400 | M14: 400 | N14: =SUM(B14:M14) -> 1400
A15: Viaticos | F15: 300 | G15: 300 | H15: 300 | I15: 300 | J15: 300 | K15: 300 | L15: 300 | M15: 300 | N15: =SUM(B15:M15) -> 2400
A16: Capacitaciones | F16: 40 | G16: 40 | H16: 40 | I16: 40 | J16: 40 | K16: 40 | L16: 40 | M16: 40 | N16: =SUM(B16:M16) -> 320
A17: Movilidad Comercial
A18: Facebook Ads | F18: 250 | G18: 250 | H18: 250 | I18: 250 | J18: 250 | K18: 250 | L18: 250 | M18: 250 | N18: =SUM(B18:M18) -> 2000
A19: Telefonia Ventas
A20: Google Ads | F20: 180 | G20: 180 | H20: 180 | I20: 180 | J20: 180 | K20: 180 | L20: 180 | M20: 180 | N20: =SUM(B20:M20) -> 1440
A21: Subtotal | B21: =SUM(B4:B20) -> 0 | C21: =SUM(C4:C20) -> 0 | D21: =SUM(D4:D20) -> 0 | E21: =SUM(E13:E20) -> 0 | F21: =SUM(F13:F20) -> 10670 | G21: =SUM(G13:G20) -> 10670 | H21: =SUM(H13:H20) -> 10670 | I21: =SUM(I13:I20) -> 10670 | J21: =SUM(J13:J20) -> 10670 | K21: =SUM(K13:K20) -> 10670 | L21: =SUM(L13:L20) -> 10970 | M21: =SUM(M13:M20) -> 10970 | N21: =SUM(B21:M21) -> 85960
A22: Centro de Costos de Marketing | B22: Ene | C22: Feb | D22: Mar | E22: Abr | F22: Mayo | G22: Jun | H22: Jul | I22: Ago | J22: Sep | K22: Oct | L22: Nov | M22: Dic | N22: AÑO
A23: Sueldo Vendedores | N23: =SUM(B23:M23) -> 0
A24: Produccion audiovisual | F24: 200 | G24: 200 | H24: 200 | I24: 200 | J24: 200 | K24: 200 | L24: 200 | M24: 200 | N24: =SUM(B24:M24) -> 1600
A25: Merchandising | N25: =SUM(B25:M25) -> 0
A26: Eventos | N26: =SUM(B26:M26) -> 0
A27: Regalos Corporativos | N27: =SUM(B27:M27) -> 0
A28: Facebook Ads | F28: 600 | G28: 600 | H28: 600 | I28: 600 | J28: 600 | K28: 600 | L28: 600 | M28: 600 | N28: =SUM(B28:M28) -> 4800
A29: Telefonia Comercial | N29: =SUM(B29:M29) -> 0
A30: Subtotal | B30: =SUM(B13:B29) -> 0 | C30: =SUM(C13:C29) -> 0 | D30: =SUM(D13:D29) -> 0 | E30: =SUM(E23:E29) -> 0 | F30: =SUM(F23:F29) -> 800 | G30: =SUM(G23:G29) -> 800 | H30: =SUM(H23:H29) -> 800 | I30: =SUM(I23:I29) -> 800 | J30: =SUM(J23:J29) -> 800 | K30: =SUM(K23:K29) -> 800 | L30: =SUM(L23:L29) -> 800 | M30: =SUM(M23:M29) -> 800 | N30: =SUM(B30:M30) -> 6400
A31: Subtotal | B31: =SUM(B14:B30) -> 0 | C31: =SUM(C14:C30) -> 0 | D31: =SUM(D14:D30) -> 0 | E31: =+E21+E30 -> 0 | F31: =+F21+F30 -> 11470 | G31: =+G21+G30 -> 11470 | H31: =+H21+H30 -> 11470 | I31: =+I21+I30 -> 11470 | J31: =+J21+J30 -> 11470 | K31: =+K21+K30 -> 11470 | L31: =+L21+L30 -> 11770 | ... N31: =+N21+N30 -> 92360
A33: Centro de Costos Administrativos (Generales) | B33: Ene | C33: Feb | D33: Mar | E33: Abr | F33: Mayo | G33: Jun | H33: Jul | I33: Ago | J33: Sep | K33: Oct | L33: Nov | M33: Dic | N33: AÑO
A34: Sueldo Administrativo | F34: 500 | G34: 500 | H34: 500 | I34: 500 | J34: 500 | K34: 500 | L34: 500 | M34: 500 | N34: =SUM(B34:M34) -> 4000
A35: Sueldo Gerencia
A36: Sueldo Contabilidad
A37: RRHH
A38: Internet
A39: Telefonia
A40: Agua
A41: Luz
A42: Alquiler Local
A43: Vigilancia
A44: Utiles de Oficina
A45: Paleria
A46: Impresiones
A47: Licencias software | F47: 200 | G47: 1000 | H47: 200 | I47: 200 | J47: 200 | K47: 200 | L47: 200 | M47: 1000 | N47: =SUM(B47:M47) -> 3200
...

Sheet DESVIACION DE GASTOS
A1: GASTOS PLANIFICADOS | B1: ENE | C1: FEB | D1: MAR | E1: ABR | F1: MAY | G1: JUN | H1: JUL | I1: AGO | J1: SEP | K1: OCT | L1: NOV | M1: DIC | N1: AÑO
A2: Centro de Costos de Producción / Operaciones | B2: Ene | C2: Feb | D2: Mar | E2: Abr | F2: Mayo | G2: Jun | H2: Jul | I2: Ago | J2: Sep | K2: Oct | L2: Nov | M2: Dic | N2: AÑO
A3: Salarios | F3: =+'GASTOS PLANIFICADOS'!F3-'GASTOS REALES'!F3 -> 8000 | N3: =SUM(B3:M3) -> 8000
A9: Beneficios | N9: =SUM(B9:M9) -> 0
A10: Subtotal | B10: =SUM(B3:B9) -> 0 | C10: =SUM(C3:C9) -> 0 | D10: =SUM(D3:D9) -> 0 | E10: =SUM(E3:E9) -> 0 | F10: =SUM(F3:F9) -> 8000 | G10: =SUM(G3:G9) -> 0 | H10: =SUM(H3:H9) -> 0 | I10: =SUM(I3:I9) -> 0 | ... N10: =SUM(N3:N9) -> 8000
A12: Centro de Costos de Ventas | B12: Ene | C12: Feb | D12: Mar | E12: Abr | F12: Mayo | G12: Jun | H12: Jul | I12: Ago | J12: Sep | K12: Oct | L12: Nov | M12: Dic | N12: AÑO
A13: Sueldo Vendedores | E13: =+'GASTOS PLANIFICADOS'!E13-'GASTOS REALES'!E13 -> 0 | F13: =+'GASTOS PLANIFICADOS'!F13-'GASTOS REALES'!F13 -> 0 | G13: =+'GASTOS PLANIFICADOS'!G13-'GASTOS REALES'!G13 -> 0 | H13: =+'GASTOS PLANIFICADOS'!H13-'GASTOS REALES'!H13 -> 0 | I13: =+'GASTOS PLANIFICADOS'!I13-'GASTOS REALES'!I13 -> 0 | J13: =+'GASTOS PLANIFICADOS'!J13-'GASTOS REALES'!J13 -> 0 | K13: =+'GASTOS PLANIFICADOS'!K13-'GASTOS REALES'!K13 -> 0 | L13: =+'GASTOS PLANIFICADOS'!L13-'GASTOS REALES'!L13 -> 0 | M13: =+'GASTOS PLANIFICADOS'!M13-'GASTOS REALES'!M13 -> 0 | N13: =SUM(B13:M13) -> 0
A14: Comisiones | E14: =+'GASTOS PLANIFICADOS'!E14-'GASTOS REALES'!E14 -> 0 | F14: =+'GASTOS PLANIFICADOS'!F14-'GASTOS REALES'!F14 -> 0 | G14: =+'GASTOS PLANIFICADOS'!G14-'GASTOS REALES'!G14 -> 0 | H14: =+'GASTOS PLANIFICADOS'!H14-'GASTOS REALES'!H14 -> 0 | I14: =+'GASTOS PLANIFICADOS'!I14-'GASTOS REALES'!I14 -> 0 | J14: =+'GASTOS PLANIFICADOS'!J14-'GASTOS REALES'!J14 -> 0 | K14: =+'GASTOS PLANIFICADOS'!K14-'GASTOS REALES'!K14 -> 0 | L14: =+'GASTOS PLANIFICADOS'!L14-'GASTOS REALES'!L14 -> 0 | M14: =+'GASTOS PLANIFICADOS'!M14-'GASTOS REALES'!M14 -> 0 | N14: =SUM(B14:M14) -> 0
A15: Viaticos | E15: =+'GASTOS PLANIFICADOS'!E15-'GASTOS REALES'!E15 -> 0 | F15: =+'GASTOS PLANIFICADOS'!F15-'GASTOS REALES'!F15 -> 0 | G15: =+'GASTOS PLANIFICADOS'!G15-'GASTOS REALES'!G15 -> 0 | H15: =+'GASTOS PLANIFICADOS'!H15-'GASTOS REALES'!H15 -> 0 | I15: =+'GASTOS PLANIFICADOS'!I15-'GASTOS REALES'!I15 -> 0 | J15: =+'GASTOS PLANIFICADOS'!J15-'GASTOS REALES'!J15 -> 0 | K15: =+'GASTOS PLANIFICADOS'!K15-'GASTOS REALES'!K15 -> 0 | L15: =+'GASTOS PLANIFICADOS'!L15-'GASTOS REALES'!L15 -> 0 | M15: =+'GASTOS PLANIFICADOS'!M15-'GASTOS REALES'!M15 -> 0 | N15: =SUM(B15:M15) -> 0
A16: Capacitaciones | E16: =+'GASTOS PLANIFICADOS'!E16-'GASTOS REALES'!E16 -> 0 | F16: =+'GASTOS PLANIFICADOS'!F16-'GASTOS REALES'!F16 -> 0 | G16: =+'GASTOS PLANIFICADOS'!G16-'GASTOS REALES'!G16 -> 0 | H16: =+'GASTOS PLANIFICADOS'!H16-'GASTOS REALES'!H16 -> 0 | I16: =+'GASTOS PLANIFICADOS'!I16-'GASTOS REALES'!I16 -> 0 | J16: =+'GASTOS PLANIFICADOS'!J16-'GASTOS REALES'!J16 -> 0 | K16: =+'GASTOS PLANIFICADOS'!K16-'GASTOS REALES'!K16 -> 0 | L16: =+'GASTOS PLANIFICADOS'!L16-'GASTOS REALES'!L16 -> 0 | M16: =+'GASTOS PLANIFICADOS'!M16-'GASTOS REALES'!M16 -> 0 | N16: =SUM(B16:M16) -> 0
A17: Movilidad Comercial | E17: =+'GASTOS PLANIFICADOS'!E17-'GASTOS REALES'!E17 -> 0 | F17: =+'GASTOS PLANIFICADOS'!F17-'GASTOS REALES'!F17 -> 0 | G17: =+'GASTOS PLANIFICADOS'!G17-'GASTOS REALES'!G17 -> 0 | H17: =+'GASTOS PLANIFICADOS'!H17-'GASTOS REALES'!H17 -> 0 | I17: =+'GASTOS PLANIFICADOS'!I17-'GASTOS REALES'!I17 -> 0 | J17: =+'GASTOS PLANIFICADOS'!J17-'GASTOS REALES'!J17 -> 0 | K17: =+'GASTOS PLANIFICADOS'!K17-'GASTOS REALES'!K17 -> 0 | L17: =+'GASTOS PLANIFICADOS'!L17-'GASTOS REALES'!L17 -> 0 | M17: =+'GASTOS PLANIFICADOS'!M17-'GASTOS REALES'!M17 -> 0
A18: Facebook Ads | E18: =+'GASTOS PLANIFICADOS'!E18-'GASTOS REALES'!E18 -> 0 | F18: =+'GASTOS PLANIFICADOS'!F18-'GASTOS REALES'!F18 -> 0 | G18: =+'GASTOS PLANIFICADOS'!G18-'GASTOS REALES'!G18 -> 0 | H18: =+'GASTOS PLANIFICADOS'!H18-'GASTOS REALES'!H18 -> 0 | I18: =+'GASTOS PLANIFICADOS'!I18-'GASTOS REALES'!I18 -> 0 | J18: =+'GASTOS PLANIFICADOS'!J18-'GASTOS REALES'!J18 -> 0 | K18: =+'GASTOS PLANIFICADOS'!K18-'GASTOS REALES'!K18 -> 0 | L18: =+'GASTOS PLANIFICADOS'!L18-'GASTOS REALES'!L18 -> 0 | M18: =+'GASTOS PLANIFICADOS'!M18-'GASTOS REALES'!M18 -> 0 | N18: =SUM(B18:M18) -> 0
A19: Telefonia Ventas | E19: =+'GASTOS PLANIFICADOS'!E19-'GASTOS REALES'!E19 -> 0 | F19: =+'GASTOS PLANIFICADOS'!F19-'GASTOS REALES'!F19 -> 0 | G19: =+'GASTOS PLANIFICADOS'!G19-'GASTOS REALES'!G19 -> 0 | H19: =+'GASTOS PLANIFICADOS'!H19-'GASTOS REALES'!H19 -> 0 | I19: =+'GASTOS PLANIFICADOS'!I19-'GASTOS REALES'!I19 -> 0 | J19: =+'GASTOS PLANIFICADOS'!J19-'GASTOS REALES'!J19 -> 0 | K19: =+'GASTOS PLANIFICADOS'!K19-'GASTOS REALES'!K19 -> 0 | L19: =+'GASTOS PLANIFICADOS'!L19-'GASTOS REALES'!L19 -> 0 | M19: =+'GASTOS PLANIFICADOS'!M19-'GASTOS REALES'!M19 -> 0
A20: Google Ads | E20: =+'GASTOS PLANIFICADOS'!E20-'GASTOS REALES'!E20 -> 0 | F20: =+'GASTOS PLANIFICADOS'!F20-'GASTOS REALES'!F20 -> 0 | G20: =+'GASTOS PLANIFICADOS'!G20-'GASTOS REALES'!G20 -> 0 | H20: =+'GASTOS PLANIFICADOS'!H20-'GASTOS REALES'!H20 -> 0 | I20: =+'GASTOS PLANIFICADOS'!I20-'GASTOS REALES'!I20 -> 0 | J20: =+'GASTOS PLANIFICADOS'!J20-'GASTOS REALES'!J20 -> 0 | K20: =+'GASTOS PLANIFICADOS'!K20-'GASTOS REALES'!K20 -> 0 | L20: =+'GASTOS PLANIFICADOS'!L20-'GASTOS REALES'!L20 -> 0 | M20: =+'GASTOS PLANIFICADOS'!M20-'GASTOS REALES'!M20 -> 0 | N20: =SUM(B20:M20) -> 0
A21: Subtotal | B21: =SUM(B4:B20) -> 0 | C21: =SUM(C4:C20) -> 0 | D21: =SUM(D4:D20) -> 0 | E21: =SUM(E13:E20) -> 0 | F21: =SUM(F13:F20) -> 0 | G21: =SUM(G13:G20) -> 0 | H21: =SUM(H13:H20) -> 0 | I21: =SUM(I13:I20) -> 0 | J21: =SUM(J13:J20) -> 0 | K21: =SUM(K13:K20) -> 0 | L21: =SUM(L13:L20) -> 0 | M21: =SUM(M13:M20) -> 0 | N21: =SUM(B21:M21) -> 0
A22: Centro de Costos de Marketing | B22: Ene | C22: Feb | D22: Mar | E22: Abr | F22: Mayo | G22: Jun | H22: Jul | I22: Ago | J22: Sep | K22: Oct | L22: Nov | M22: Dic | N22: AÑO
A23: Sueldo Vendedores | N23: =SUM(B23:M23) -> 0
A24: Produccion audiovisual | F24: 200 | G24: 200 | H24: 200 | I24: 200 | J24: 200 | K24: 200 | L24: 200 | M24: 200 | N24: =SUM(B24:M24) -> 1600
A25: Merchandising | N25: =SUM(B25:M25) -> 0
A26: Eventos | N26: =SUM(B26:M26) -> 0
A27: Regalos Corporativos | N27: =SUM(B27:M27) -> 0
A28: Facebook Ads | F28: 600 | G28: 600 | H28: 600 | I28: 600 | J28: 600 | K28: 600 | L28: 600 | M28: 600 | N28: =SUM(B28:M28) -> 4800
A29: Telefonia Comercial | N29: =SUM(B29:M29) -> 0
A30: Subtotal | B30: =SUM(B13:B29) -> 0 | C30: =SUM(C13:C29) -> 0 | D30: =SUM(D13:D29) -> 0 | E30: =SUM(E23:E29) -> 0 | F30: =SUM(F23:F29) -> 800 | G30: =SUM(G23:G29) -> 800 | H30: =SUM(H23:H29) -> 800 | I30: =SUM(I23:I29) -> 800 | J30: =SUM(J23:J29) -> 800 | K30: =SUM(K23:K29) -> 800 | L30: =SUM(L23:L29) -> 800 | M30: =SUM(M23:M29) -> 800 | N30: =SUM(B30:M30) -> 6400
A31: Subtotal | B31: =SUM(B14:B30) -> 0 | C31: =SUM(C14:C30) -> 0 | D31: =SUM(D14:D30) -> 0 | E31: =+E21+E30 -> 0 | F31: =+F21+F30 -> 800 | G31: =+G21+G30 -> 800 | H31: =+H21+H30 -> 800 | I31: =+I21+I30 -> 800 | J31: =+J21+J30 -> 800 | K31: =+K21+K30 -> 800 | L31: =+L21+L30 -> 800 | ... N31: =+N21+N30 -> 6400
A33: Centro de Costos Administrativos (Generales) | B33: Ene | C33: Feb | D33: Mar | E33: Abr | F33: Mayo | G33: Jun | H33: Jul | I33: Ago | J33: Sep | K33: Oct | L33: Nov | M33: Dic | N33: AÑO
A34: Sueldo Administrativo | F34: 500 | G34: 500 | H34: 500 | I34: 500 | J34: 500 | K34: 500 | L34: 500 | M34: 500 | N34: =SUM(B34:M34) -> 4000
A35: Sueldo Gerencia
A36: Sueldo Contabilidad
A37: RRHH
A38: Internet
A39: Telefonia
A40: Agua
A41: Luz
A42: Alquiler Local
A43: Vigilancia
A44: Utiles de Oficina
A45: Paleria
A46: Impresiones
A47: Licencias software | F47: 200 | G47: 1000 | H47: 200 | I47: 200 | J47: 200 | K47: 200 | L47: 200 | M47: 1000 | N47: =SUM(B47:M47) -> 3200
...

Sheet ANALISIS DE GASTOS
A1: Categoría de gastos | B1: Gastos planificados | C1: Gastos reales | D1: Desviaciones de gastos | E1: Porcentaje de desviación
A2: =+'GASTOS PLANIFICADOS'!A2 -> Centro de Costos de Producción / Operaciones | B2: =+'GASTOS PLANIFICADOS'!N10 -> 10000 | C2: =+'GASTOS REALES'!N10 -> 6000 | D2: =+'DESVIACION DE GASTOS'!N10 -> 8000 | E2: =+(C2-B2)/B2 -> -0.4
A3: =+'GASTOS PLANIFICADOS'!A12 -> Centro de Costos de Ventas | B3: =+'GASTOS PLANIFICADOS'!N30 -> 6400 | C3: =+'GASTOS REALES'!N31 -> 92360 | D3: =+'DESVIACION DE GASTOS'!N31 -> 6400 | E3: =+(C3-B3)/B3 -> 13.43125
A4: =+'GASTOS PLANIFICADOS'!A33 -> Centro de Costos Administrativos (Generales) | B4: =+'GASTOS PLANIFICADOS'!N52 -> 42400 | C4: =+'GASTOS REALES'!N52 -> 42400 | D4: =+'DESVIACION DE GASTOS'!N52 -> 42400 | E4: =+(C4-B4)/B4 -> 0
A5: =+'GASTOS PLANIFICADOS'!A54 -> Centro de Costos de Servicios / Soporte | B5: =+'GASTOS PLANIFICADOS'!N63 -> 32000 | C5: =+'GASTOS PLANIFICADOS'!N63 -> 32000 | D5: =+'DESVIACION DE GASTOS'!N63 -> 32000 | E5: =+(C5-B5)/B5 -> 0
A6: TOTALES | B6: =SUM(B2:B5) -> 90800 | C6: =SUM(C2:C5) -> 172760 | D6: =+B6-C6 -> -81960 | E6: =+(C6-B6)/B6 -> 0.90264317
